<?xml version="1.0"?>
<sdf version="1.8">
  <model name="diff_drive_robot">
    <pose>0 0 0.1 0 0 0</pose>

    <!-- base_link -->
    <link name="base_link">
      <inertial>
        <mass>5.0</mass>
        <inertia><ixx>0.1</ixx><iyy>0.1</iyy><izz>0.18</izz></inertia>
      </inertial>
      <collision name="base_col">
        <geometry><cylinder><radius>0.175</radius><length>0.1</length></cylinder></geometry>
      </collision>
      <visual name="base_vis">
        <geometry><cylinder><radius>0.175</radius><length>0.1</length></cylinder></geometry>
        <material><ambient>0.2 0.4 0.8 1</ambient></material>
      </visual>
    </link>

    <!-- Left wheel -->
    <link name="left_wheel">
      <pose>0 0.14 -0.05 -1.5707 0 0</pose>
      <inertial><mass>0.5</mass><inertia><ixx>0.001</ixx><iyy>0.001</iyy><izz>0.001</izz></inertia></inertial>
      <collision name="col"><geometry><cylinder><radius>0.05</radius><length>0.04</length></cylinder></geometry></collision>
      <visual name="vis">
        <geometry><cylinder><radius>0.05</radius><length>0.04</length></cylinder></geometry>
        <material><ambient>0.1 0.1 0.1 1</ambient></material>
      </visual>
    </link>
    <joint name="left_wheel_joint" type="revolute">
      <parent>base_link</parent><child>left_wheel</child>
      <axis><xyz>0 0 1</xyz><limit><lower>-1.79e308</lower><upper>1.79e308</upper></limit></axis>
    </joint>

    <!-- Right wheel -->
    <link name="right_wheel">
      <pose>0 -0.14 -0.05 -1.5707 0 0</pose>
      <inertial><mass>0.5</mass><inertia><ixx>0.001</ixx><iyy>0.001</iyy><izz>0.001</izz></inertia></inertial>
      <collision name="col"><geometry><cylinder><radius>0.05</radius><length>0.04</length></cylinder></geometry></collision>
      <visual name="vis">
        <geometry><cylinder><radius>0.05</radius><length>0.04</length></cylinder></geometry>
        <material><ambient>0.1 0.1 0.1 1</ambient></material>
      </visual>
    </link>
    <joint name="right_wheel_joint" type="revolute">
      <parent>base_link</parent><child>right_wheel</child>
      <axis><xyz>0 0 1</xyz><limit><lower>-1.79e308</lower><upper>1.79e308</upper></limit></axis>
    </joint>

    <!-- Caster -->
    <link name="caster">
      <pose>0.105 0 -0.08 0 0 0</pose>
      <inertial><mass>0.1</mass><inertia><ixx>0.0001</ixx><iyy>0.0001</iyy><izz>0.0001</izz></inertia></inertial>
      <collision name="col"><geometry><sphere><radius>0.03</radius></sphere></geometry>
        <surface><friction><ode><mu>0</mu><mu2>0</mu2></ode></friction></surface>
      </collision>
      <visual name="vis"><geometry><sphere><radius>0.03</radius></sphere></geometry>
        <material><ambient>0.5 0.5 0.5 1</ambient></material></visual>
    </link>
    <joint name="caster_joint" type="ball">
      <parent>base_link</parent><child>caster</child>
    </joint>

    <!-- LiDAR link -->
    <link name="lidar_link">
      <pose>0 0 0.12 0 0 0</pose>
      <inertial><mass>0.1</mass><inertia><ixx>0.0001</ixx><iyy>0.0001</iyy><izz>0.0001</izz></inertia></inertial>
      <visual name="vis">
        <geometry><cylinder><radius>0.035</radius><length>0.06</length></cylinder></geometry>
        <material><ambient>0.05 0.05 0.05 1</ambient></material>
      </visual>
      <sensor name="lidar" type="gpu_lidar">
        <update_rate>10</update_rate>
        <lidar>
          <scan>
            <horizontal>
              <samples>360</samples>
              <resolution>1</resolution>
              <min_angle>-3.14159</min_angle>
              <max_angle>3.14159</max_angle>
            </horizontal>
          </scan>
          <range><min>0.12</min><max>5.0</max><resolution>0.01</resolution></range>
          <noise><type>gaussian</type><mean>0</mean><stddev>0.01</stddev></noise>
        </lidar>
        <always_on>1</always_on>
        <visualize>false</visualize>
        <topic>scan</topic>
      </sensor>
    </link>
    <joint name="lidar_joint" type="fixed">
      <parent>base_link</parent><child>lidar_link</child>
    </joint>

    <!-- ── Plugins ── -->

    <!-- Differential drive -->
    <plugin filename="ignition-gazebo-diff-drive-system"
            name="ignition::gazebo::systems::DiffDrive">
      <left_joint>left_wheel_joint</left_joint>
      <right_joint>right_wheel_joint</right_joint>
      <wheel_separation>0.28</wheel_separation>
      <wheel_radius>0.05</wheel_radius>
      <max_linear_acceleration>2</max_linear_acceleration>
      <max_angular_acceleration>4</max_angular_acceleration>
      <topic>cmd_vel</topic>
      <odom_topic>odometry</odom_topic>
      <frame_id>odom</frame_id>
      <child_frame_id>base_link</child_frame_id>
    </plugin>

    <!-- Odometry publisher -->
    <plugin filename="ignition-gazebo-odometry-publisher-system"
            name="ignition::gazebo::systems::OdometryPublisher">
      <odom_frame>odom</odom_frame>
      <robot_base_frame>base_link</robot_base_frame>
    </plugin>

    <!-- Joint state publisher (for TF) -->
    <plugin filename="ignition-gazebo-joint-state-publisher-system"
            name="ignition::gazebo::systems::JointStatePublisher"/>

    <!-- Sensor system (for LiDAR) -->
    <plugin filename="ignition-gazebo-sensors-system"
            name="ignition::gazebo::systems::Sensors">
      <render_engine>ogre2</render_engine>
    </plugin>

  </model>
</sdf>
