<?xml version="1.0"?>
<robot name="diff_drive_robot" xmlns:xacro="http://www.ros.org/wiki/xacro">

  <!-- ── Parameters ──────────────────────────────────────────────────────── -->
  <xacro:property name="base_radius"  value="0.175"/>
  <xacro:property name="base_height"  value="0.10"/>
  <xacro:property name="wheel_radius" value="0.05"/>
  <xacro:property name="wheel_width"  value="0.04"/>
  <xacro:property name="wheel_sep"    value="0.28"/>
  <xacro:property name="lidar_height" value="0.12"/>

  <!-- ── Materials ───────────────────────────────────────────────────────── -->
  <material name="grey"><color rgba="0.5 0.5 0.5 1"/></material>
  <material name="black"><color rgba="0.1 0.1 0.1 1"/></material>
  <material name="blue"><color rgba="0.2 0.4 0.8 1"/></material>

  <!-- ── base_footprint ──────────────────────────────────────────────────── -->
  <link name="base_footprint"/>

  <joint name="base_joint" type="fixed">
    <parent link="base_footprint"/>
    <child  link="base_link"/>
    <origin xyz="0 0 ${wheel_radius}" rpy="0 0 0"/>
  </joint>

  <!-- ── base_link ───────────────────────────────────────────────────────── -->
  <link name="base_link">
    <visual>
      <geometry><cylinder radius="${base_radius}" length="${base_height}"/></geometry>
      <material name="blue"/>
    </visual>
    <collision>
      <geometry><cylinder radius="${base_radius}" length="${base_height}"/></geometry>
    </collision>
    <inertial>
      <mass value="5.0"/>
      <inertia ixx="0.1" ixy="0" ixz="0" iyy="0.1" iyz="0" izz="0.18"/>
    </inertial>
  </link>

  <!-- ── Left wheel ──────────────────────────────────────────────────────── -->
  <joint name="left_wheel_joint" type="continuous">
    <parent link="base_link"/>
    <child  link="left_wheel"/>
    <origin xyz="0 ${wheel_sep/2} ${-base_height/2}" rpy="${-pi/2} 0 0"/>
    <axis xyz="0 0 1"/>
  </joint>

  <link name="left_wheel">
    <visual>
      <geometry><cylinder radius="${wheel_radius}" length="${wheel_width}"/></geometry>
      <material name="black"/>
    </visual>
    <collision>
      <geometry><cylinder radius="${wheel_radius}" length="${wheel_width}"/></geometry>
    </collision>
    <inertial>
      <mass value="0.5"/>
      <inertia ixx="0.001" ixy="0" ixz="0" iyy="0.001" iyz="0" izz="0.001"/>
    </inertial>
  </link>

  <!-- ── Right wheel ─────────────────────────────────────────────────────── -->
  <joint name="right_wheel_joint" type="continuous">
    <parent link="base_link"/>
    <child  link="right_wheel"/>
    <origin xyz="0 ${-wheel_sep/2} ${-base_height/2}" rpy="${-pi/2} 0 0"/>
    <axis xyz="0 0 1"/>
  </joint>

  <link name="right_wheel">
    <visual>
      <geometry><cylinder radius="${wheel_radius}" length="${wheel_width}"/></geometry>
      <material name="black"/>
    </visual>
    <collision>
      <geometry><cylinder radius="${wheel_radius}" length="${wheel_width}"/></geometry>
    </collision>
    <inertial>
      <mass value="0.5"/>
      <inertia ixx="0.001" ixy="0" ixz="0" iyy="0.001" iyz="0" izz="0.001"/>
    </inertial>
  </link>

  <!-- ── Caster (passive) ────────────────────────────────────────────────── -->
  <joint name="caster_joint" type="fixed">
    <parent link="base_link"/>
    <child  link="caster_link"/>
    <origin xyz="${base_radius*0.6} 0 ${-base_height/2}" rpy="0 0 0"/>
  </joint>

  <link name="caster_link">
    <visual>
      <geometry><sphere radius="${wheel_radius*0.6}"/></geometry>
      <material name="grey"/>
    </visual>
    <collision>
      <geometry><sphere radius="${wheel_radius*0.6}"/></geometry>
    </collision>
    <inertial>
      <mass value="0.1"/>
      <inertia ixx="0.0001" ixy="0" ixz="0" iyy="0.0001" iyz="0" izz="0.0001"/>
    </inertial>
  </link>

  <!-- ── LiDAR ───────────────────────────────────────────────────────────── -->
  <joint name="lidar_joint" type="fixed">
    <parent link="base_link"/>
    <child  link="lidar_link"/>
    <origin xyz="0 0 ${base_height/2 + lidar_height/2}" rpy="0 0 0"/>
  </joint>

  <link name="lidar_link">
    <visual>
      <geometry><cylinder radius="0.035" length="${lidar_height}"/></geometry>
      <material name="black"/>
    </visual>
    <collision>
      <geometry><cylinder radius="0.035" length="${lidar_height}"/></geometry>
    </collision>
    <inertial>
      <mass value="0.2"/>
      <inertia ixx="0.0001" ixy="0" ixz="0" iyy="0.0001" iyz="0" izz="0.0001"/>
    </inertial>
  </link>

  <!-- ── Gazebo differential drive plugin ────────────────────────────────── -->
  <gazebo>
    <plugin name="diff_drive" filename="libgazebo_ros_diff_drive.so">
      <left_joint>left_wheel_joint</left_joint>
      <right_joint>right_wheel_joint</right_joint>
      <wheel_separation>${wheel_sep}</wheel_separation>
      <wheel_diameter>${2*wheel_radius}</wheel_diameter>
      <max_wheel_torque>20</max_wheel_torque>
      <max_wheel_acceleration>2.0</max_wheel_acceleration>
      <command_topic>cmd_vel</command_topic>
      <publish_odom>true</publish_odom>
      <publish_odom_tf>false</publish_odom_tf>
      <odometry_topic>odom</odometry_topic>
      <odometry_frame>odom</odometry_frame>
      <robot_base_frame>base_link</robot_base_frame>
    </plugin>
  </gazebo>

  <!-- ── Gazebo LiDAR sensor ─────────────────────────────────────────────── -->
  <gazebo reference="lidar_link">
    <sensor name="lidar" type="ray">
      <always_on>true</always_on>
      <update_rate>10</update_rate>
      <ray>
        <scan>
          <horizontal>
            <samples>360</samples>
            <resolution>1</resolution>
            <min_angle>-3.14159</min_angle>
            <max_angle>3.14159</max_angle>
          </horizontal>
        </scan>
        <range>
          <min>0.12</min>
          <max>5.0</max>
          <resolution>0.01</resolution>
        </range>
        <noise>
          <type>gaussian</type>
          <mean>0.0</mean>
          <stddev>0.01</stddev>
        </noise>
      </ray>
      <plugin name="lidar_plugin" filename="libgazebo_ros_ray_sensor.so">
        <ros><remapping>~/out:=scan</remapping></ros>
        <output_type>sensor_msgs/LaserScan</output_type>
        <frame_name>lidar_link</frame_name>
      </plugin>
    </sensor>
  </gazebo>

</robot>
